Workbook
Name Cost_Input: 'Investor-Inputs'!$N$19
Name Cost_Map: 'Investor-Inputs'!$M$11:$N$14
Name Cost_Weight: 'Investor-Inputs'!$N$27
Name Input: 'Investor-Inputs'!$G$23
Name Investor_Map: 'Investor-Inputs'!$G$11:$H$14
Name Return_Input: 'Investor-Inputs'!$J$19
Name Return_Map: 'Investor-Inputs'!$J$11:$K$14
Name Return_Weight: 'Investor-Inputs'!$J$27
Name SIP_Input: 'Investor-Inputs'!$G$19
Name SIP_Weight: 'Investor-Inputs'!$G$27
Name SIPInput: 'Investor-Inputs'!$G$20

Sheet Investor-Inputs
H3: Investor Profiling and Fund Recommendation as per User Requirements
A7: User Inputs | D7: Select your options
B8: Select Investor Type: | D8: Conservative
B9: Select Retrun Priority | D9: Medium
B10: Select Cost Sensitivity: | D10: High | G10: Investor Type | J10: Return Priority | M10: Cost Sensitivity
G11: Investor Type | H11: Value | J11: Return Priority | K11: Value | M11: Cost | N11: Value
G12: Conservative | H12: 3 | J12: Low | K12: 1 | M12: Low | N12: 3
G13: Moderate | H13: 2 | J13: Medium | K13: 2 | M13: Medium | N13: 2
G14: Aggressive | H14: 1 | J14: High | K14: 3 | M14: High | N14: 1
A19: Calculations | D19: Value Mapping as per Investor | G19: =VLOOKUP(D8,G12:H14,2,FALSE) -> 3 | J19: =VLOOKUP(D9,J12:K14,2,FALSE) -> 2 | N19: =VLOOKUP(D10,M12:N14,2,FALSE) -> 1
D23: Total Value | G23: =SIP_Input+Return_Input+Cost_Input -> 6
D27: Normalized Value | G27: =SIP_Input/Input -> 0.5 | J27: =Return_Input/Input -> 0.33333333 | N27: =Cost_Input/Input -> 0.16666667
A29: Recommendations
B31: See next page for mutual fund recommendations based on user inputs (See the fina column Ranks)
B33: See last page for top 10 funds based on user inputs (Visual Analysis)

Sheet mutual-funds
C6: Fund Name | D6: Rating | E6: VR Opinion | F6: Category | G6: 1 Year Returns (%) | H6: 1 Year SIP Returns (%) | I6: 3 Year Returns (%) | J6: 3 Year SIP Returns (%) | K6: 5 Year Returns (%) | L6: 5 Year SIP Returns (%) | M6: Expense Ratio (%) | N6: Riskometer | O6: Return Grade | P6: Plan | Q6: ReturnScore | R6: SIPScore | S6: CostScore | T6: MFScore | U6: Rank
C7: Aditya Birla Sun Life Large Cap Fund - Regular Plan | D7: 4 | E7: Unlock | F7: Equity: Large Cap | G7: -0.47 | H7: -6.31 | I7: 13.07 | J7: 5.14 | K7: 12.5 | L7: 9.15 | M7: 1.58 | N7: Very High | O7: Above Avg. | P7: Direct | Q7: =I7*0.4+K7*0.5 -> 11.478 | R7: =(L7+J7)/2 -> 7.145 | S7: =(M7+K7)/2 -> 7.04 | T7: =('Investor-Inputs'!$G$19 * Q7) + ('Investor-Inputs'!$J$19 * R7) + ('Investor-Inputs'!$N$19 * S7) -> 55.764 | U7: =_xlfn.RANK.EQ(T7,$T$7:$T$592,0) -> 256
C8: Aditya Birla Sun Life Nifty 50 Equal Weight Index Fund - Regular Plan | D8: 4 | E8: Unlock | F8: Equity: Large Cap | G8: 6.69 | H8: 2.58 | I8: 15.81 | J8: 8.65 | M8: 1.1 | N8: Very High | O8: Above Avg. | P8: Direct | Q8: =I8*0.4+K8*0.5 -> 6.324 | R8: =(L8+J8)/2 -> 4.325 | S8: =(M8+K8)/2 -> 0.55 | T8: =('Investor-Inputs'!$G$19 * Q8) + ('Investor-Inputs'!$J$19 * R8) + ('Investor-Inputs'!$N$19 * S8) -> 28.172 | U8: =_xlfn.RANK.EQ(T8,$T$7:$T$592,0) -> 554
C9: Aditya Birla Sun Life Nifty Next 50 Index Fund - Regular Plan | D9: 4 | E9: Unlock | F9: Equity: Large Cap | G9: 8.12 | H9: 6.8 | I9: 20.35 | J9: 10.29 | M9: 0.89 | N9: Very High | O9: Above Avg. | P9: Direct | Q9: =I9*0.4+K9*0.5 -> 8.14 | R9: =(L9+J9)/2 -> 5.145 | S9: =(M9+K9)/2 -> 0.445 | T9: =('Investor-Inputs'!$G$19 * Q9) + ('Investor-Inputs'!$J$19 * R9) + ('Investor-Inputs'!$N$19 * S9) -> 35.155 | U9: =_xlfn.RANK.EQ(T9,$T$7:$T$592,0) -> 389
C10: Bandhan Large Cap Fund - Regular Plan | D10: 4 | E10: Unlock | F10: Equity: Large Cap | G10: 2.79 | H10: -2.89 | I10: 14.78 | J10: 7.14 | K10: 12.89 | L10: 10.4 | M10: 2.24 | N10: Very High | O10: Above Avg. | P10: Direct | Q10: =I10*0.4+K10*0.5 -> 12.357 | R10: =(L10+J10)/2 -> 8.77 | S10: =(M10+K10)/2 -> 7.565 | T10: =('Investor-Inputs'!$G$19 * Q10) + ('Investor-Inputs'!$J$19 * R10) + ('Investor-Inputs'!$N$19 * S10) -> 62.176 | U10: =_xlfn.RANK.EQ(T10,$T$7:$T$592,0) -> 226
C11: Baroda BNP Paribas Large Cap Fund - Regular Plan | D11: 4 | E11: Unlock | F11: Equity: Large Cap | G11: 2.57 | H11: -0.27 | I11: 14.44 | J11: 6.72 | K11: 13.07 | L11: 10.53 | M11: 2 | N11: Very High | O11: Above Avg. | P11: Direct | Q11: =I11*0.4+K11*0.5 -> 12.311 | R11: =(L11+J11)/2 -> 8.625 | S11: =(M11+K11)/2 -> 7.535 | T11: =('Investor-Inputs'!$G$19 * Q11) + ('Investor-Inputs'!$J$19 * R11) + ('Investor-Inputs'!$N$19 * S11) -> 61.718 | U11: =_xlfn.RANK.EQ(T11,$T$7:$T$592,0) -> 230
C12: Canara Robeco Large Cap Fund - Regular Plan | D12: 4 | E12: Unlock | F12: Equity: Large Cap | G12: -1.43 | H12: -6.93 | I12: 12.6 | J12: 4.99 | K12: 11.37 | L12: 8.71 | M12: 1.75 | N12: Very High | O12: Avg. | P12: Direct | Q12: =I12*0.4+K12*0.5 -> 10.725 | R12: =(L12+J12)/2 -> 6.85 | S12: =(M12+K12)/2 -> 6.56 | T12: =('Investor-Inputs'!$G$19 * Q12) + ('Investor-Inputs'!$J$19 * R12) + ('Investor-Inputs'!$N$19 * S12) -> 52.435 | U12: =_xlfn.RANK.EQ(T12,$T$7:$T$592,0) -> 275
C13: DSP Large Cap Fund - Regular Plan | D13: 5 | E13: Unlock | F13: Equity: Large Cap | G13: -2.41 | H13: -6.84 | I13: 15.09 | J13: 6.23 | K13: 12.28 | L13: 10.35 | M13: 2.52 | N13: Very High | O13: Above Avg. | P13: Direct | Q13: =I13*0.4+K13*0.5 -> 12.176 | R13: =(L13+J13)/2 -> 8.29 | S13: =(M13+K13)/2 -> 7.4 | T13: =('Investor-Inputs'!$G$19 * Q13) + ('Investor-Inputs'!$J$19 * R13) + ('Investor-Inputs'!$N$19 * S13) -> 60.508 | U13: =_xlfn.RANK.EQ(T13,$T$7:$T$592,0) -> 236
C14: DSP Nifty 50 Equal Weight Index Fund - Regular Plan | D14: 5 | E14: Unlock | F14: Equity: Large Cap | G14: 6.81 | H14: 2.67 | I14: 15.95 | J14: 8.77 | K14: 14.83 | L14: 12.24 | M14: 0.95 | N14: Very High | O14: Above Avg. | P14: Direct | Q14: =I14*0.4+K14*0.5 -> 13.795 | R14: =(L14+J14)/2 -> 10.505 | S14: =(M14+K14)/2 -> 7.89 | T14: =('Investor-Inputs'!$G$19 * Q14) + ('Investor-Inputs'!$J$19 * R14) + ('Investor-Inputs'!$N$19 * S14) -> 70.285 | U14: =_xlfn.RANK.EQ(T14,$T$7:$T$592,0) -> 192
C15: DSP Nifty Next 50 Index Fund - Regular Plan | D15: 4 | E15: Unlock | F15: Equity: Large Cap | G15: 8.35 | H15: 6.86 | I15: 20.83 | J15: 10.65 | K15: 15.1 | L15: 13.33 | M15: 0.98 | N15: Very High | O15: High | P15: Direct | Q15: =I15*0.4+K15*0.5 -> 15.882 | R15: =(L15+J15)/2 -> 11.99 | S15: =(M15+K15)/2 -> 8.04 | T15: =('Investor-Inputs'!$G$19 * Q15) + ('Investor-Inputs'!$J$19 * R15) + ('Investor-Inputs'!$N$19 * S15) -> 79.666 | U15: =_xlfn.RANK.EQ(T15,$T$7:$T$592,0) -> 132
C16: Edelweiss Large Cap Fund - Regular Plan | D16: 4 | E16: Unlock | F16: Equity: Large Cap | G16: -0.09 | H16: -5.13 | I16: 12.29 | J16: 4.59 | K16: 12.11 | L16: 9 | M16: 2.12 | N16: Very High | O16: Avg. | P16: Direct | Q16: =I16*0.4+K16*0.5 -> 10.971 | R16: =(L16+J16)/2 -> 6.795 | S16: =(M16+K16)/2 -> 7.115 | T16: =('Investor-Inputs'!$G$19 * Q16) + ('Investor-Inputs'!$J$19 * R16) + ('Investor-Inputs'!$N$19 * S16) -> 53.618 | U16: =_xlfn.RANK.EQ(T16,$T$7:$T$592,0) -> 273
C17: HDFC Large Cap Fund - Regular Plan | D17: 5 | E17: Unlock | F17: Equity: Large Cap | G17: -1.59 | H17: -6.6 | I17: 12.48 | J17: 3.95 | K17: 13.84 | L17: 9.59 | M17: 1.58 | N17: Very High | O17: Above Avg. | P17: Direct | Q17: =I17*0.4+K17*0.5 -> 11.912 | R17: =(L17+J17)/2 -> 6.77 | S17: =(M17+K17)/2 -> 7.71 | T17: =('Investor-Inputs'!$G$19 * Q17) + ('Investor-Inputs'!$J$19 * R17) + ('Investor-Inputs'!$N$19 * S17) -> 56.986 | U17: =_xlfn.RANK.EQ(T17,$T$7:$T$592,0) -> 246
C18: HDFC NIFTY 100 Equal Weight Index Fund - Regular Plan | D18: 4 | E18: Unlock | F18: Equity: Large Cap | G18: 7.88 | H18: 4.9 | I18: 18.08 | J18: 9.68 | M18: 0.88 | N18: Very High | O18: Above Avg. | P18: Direct | Q18: =I18*0.4+K18*0.5 -> 7.232 | R18: =(L18+J18)/2 -> 4.84 | S18: =(M18+K18)/2 -> 0.44 | T18: =('Investor-Inputs'!$G$19 * Q18) + ('Investor-Inputs'!$J$19 * R18) + ('Investor-Inputs'!$N$19 * S18) -> 31.816 | U18: =_xlfn.RANK.EQ(T18,$T$7:$T$592,0) -> 504
C19: HDFC NIFTY50 Equal Weight Index Fund - Regular Plan | D19: 5 | E19: Unlock | F19: Equity: Large Cap | G19: 6.85 | H19: 2.71 | I19: 16.02 | J19: 8.85 | M19: 1 | N19: Very High | O19: Above Avg. | P19: Direct | Q19: =I19*0.4+K19*0.5 -> 6.408 | R19: =(L19+J19)/2 -> 4.425 | S19: =(M19+K19)/2 -> 0.5 | T19: =('Investor-Inputs'!$G$19 * Q19) + ('Investor-Inputs'!$J$19 * R19) + ('Investor-Inputs'!$N$19 * S19) -> 28.574 | U19: =_xlfn.RANK.EQ(T19,$T$7:$T$592,0) -> 546
C20: ICICI Prudential BHARAT 22 FOF | D20: 5 | E20: Unlock | F20: Equity: Large Cap | G20: 17.4 | H20: 18.98 | I20: 25.53 | J20: 16.37 | K20: 28 | L20: 23.73 | M20: 0.14 | N20: Very High | O20: High | P20: Direct | Q20: =I20*0.4+K20*0.5 -> 24.212 | R20: =(L20+J20)/2 -> 20.05 | S20: =(M20+K20)/2 -> 14.07 | T20: =('Investor-Inputs'!$G$19 * Q20) + ('Investor-Inputs'!$J$19 * R20) + ('Investor-Inputs'!$N$19 * S20) -> 126.806 | U20: =_xlfn.RANK.EQ(T20,$T$7:$T$592,0) -> 7
C21: ICICI Prudential Large Cap Fund | D21: 5 | E21: Unlock | F21: Equity: Large Cap | G21: 0.07 | H21: -5.94 | I21: 15.26 | J21: 6.51 | K21: 14.67 | L21: 11.25 | M21: 3.59 | N21: Very High | O21: Above Avg. | P21: Direct | Q21: =I21*0.4+K21*0.5 -> 13.439 | R21: =(L21+J21)/2 -> 8.88 | S21: =(M21+K21)/2 -> 9.13 | T21: =('Investor-Inputs'!$G$19 * Q21) + ('Investor-Inputs'!$J$19 * R21) + ('Investor-Inputs'!$N$19 * S21) -> 67.207 | U21: =_xlfn.RANK.EQ(T21,$T$7:$T$592,0) -> 202
C22: ICICI Prudential Nifty 100 Low Volatility 30 ETF FOF | D22: 4 | E22: Unlock | F22: Equity: Large Cap | G22: 1.08 | H22: -4.13 | I22: 13.56 | J22: 5.49 | K22: 12.11 | L22: 9.43 | M22: 0.58 | N22: Very High | O22: Avg. | P22: Direct | Q22: =I22*0.4+K22*0.5 -> 11.479 | R22: =(L22+J22)/2 -> 7.46 | S22: =(M22+K22)/2 -> 6.345 | T22: =('Investor-Inputs'!$G$19 * Q22) + ('Investor-Inputs'!$J$19 * R22) + ('Investor-Inputs'!$N$19 * S22) -> 55.702 | U22: =_xlfn.RANK.EQ(T22,$T$7:$T$592,0) -> 258
C23: ICICI Prudential Nifty50 Equal Weight Index Fund | D23: 4 | E23: Unlock | F23: Equity: Large Cap | G23: 6.65 | H23: 2.53 | I23: 15.8 | J23: 8.67 | M23: 1.25 | N23: Very High | O23: Above Avg. | P23: Direct | Q23: =I23*0.4+K23*0.5 -> 6.32 | R23: =(L23+J23)/2 -> 4.335 | S23: =(M23+K23)/2 -> 0.625 | T23: =('Investor-Inputs'!$G$19 * Q23) + ('Investor-Inputs'!$J$19 * R23) + ('Investor-Inputs'!$N$19 * S23) -> 28.255 | U23: =_xlfn.RANK.EQ(T23,$T$7:$T$592,0) -> 552
C24: Invesco India Largecap Fund - Regular Plan | D24: 4 | E24: Unlock | F24: Equity: Large Cap | G24: 2.12 | H24: -3.12 | I24: 15.53 | J24: 7 | K24: 13.55 | L24: 10.5 | M24: 2.08 | N24: Very High | O24: Above Avg. | P24: Direct | Q24: =I24*0.4+K24*0.5 -> 12.987 | R24: =(L24+J24)/2 -> 8.75 | S24: =(M24+K24)/2 -> 7.815 | T24: =('Investor-Inputs'!$G$19 * Q24) + ('Investor-Inputs'!$J$19 * R24) + ('Investor-Inputs'!$N$19 * S24) -> 64.276 | U24: =_xlfn.RANK.EQ(T24,$T$7:$T$592,0) -> 212
C25: Kotak Large Cap Fund - Regular Plan | D25: 4 | E25: Unlock | F25: Equity: Large Cap | G25: 0.86 | H25: -5.19 | I25: 12.92 | J25: 5.64 | K25: 12.12 | L25: 9.24 | M25: 1.89 | N25: Very High | O25: Avg. | P25: Direct | Q25: =I25*0.4+K25*0.5 -> 11.228 | R25: =(L25+J25)/2 -> 7.44 | S25: =(M25+K25)/2 -> 7.005 | T25: =('Investor-Inputs'!$G$19 * Q25) + ('Investor-Inputs'!$J$19 * R25) + ('Investor-Inputs'!$N$19 * S25) -> 55.569 | U25: =_xlfn.RANK.EQ(T25,$T$7:$T$592,0) -> 262
C26: Kotak Nifty Next 50 Index Fund - Regular Plan | D26: 4 | E26: Unlock | F26: Equity: Large Cap | G26: 8.33 | H26: 6.98 | I26: 20.72 | J26: 10.66 | K26: 15.03 | L26: 13.29 | M26: 0.9 | N26: Very High | O26: High | P26: Direct | Q26: =I26*0.4+K26*0.5 -> 15.803 | R26: =(L26+J26)/2 -> 11.975 | S26: =(M26+K26)/2 -> 7.965 | T26: =('Investor-Inputs'!$G$19 * Q26) + ('Investor-Inputs'!$J$19 * R26) + ('Investor-Inputs'!$N$19 * S26) -> 79.324 | U26: =_xlfn.RANK.EQ(T26,$T$7:$T$592,0) -> 134
C27: Mirae Asset Diversified Equity Allocator Passive FoF - Regular Plan | D27: 4 | E27: Unlock | F27: Equity: Large Cap | G27: 3.38 | H27: -1.33 | I27: 14.48 | J27: 6.77 | K27: 13.29 | L27: 10.45 | M27: 0.11 | N27: Very High | O27: Above Avg. | P27: Direct | Q27: =I27*0.4+K27*0.5 -> 12.437 | R27: =(L27+J27)/2 -> 8.61 | S27: =(M27+K27)/2 -> 6.7 | T27: =('Investor-Inputs'!$G$19 * Q27) + ('Investor-Inputs'!$J$19 * R27) + ('Investor-Inputs'!$N$19 * S27) -> 61.231 | U27: =_xlfn.RANK.EQ(T27,$T$7:$T$592,0) -> 232
C28: Navi Nifty Next 50 Index Fund - Regular Plan | D28: 4 | E28: Unlock | F28: Equity: Large Cap | G28: 7.86 | H28: 6.38 | I28: 20.48 | J28: 10.34 | M28: 1.07 | N28: Very High | O28: Above Avg. | P28: Direct | Q28: =I28*0.4+K28*0.5 -> 8.192 | R28: =(L28+J28)/2 -> 5.17 | S28: =(M28+K28)/2 -> 0.535 | T28: =('Investor-Inputs'!$G$19 * Q28) + ('Investor-Inputs'!$J$19 * R28) + ('Investor-Inputs'!$N$19 * S28) -> 35.451 | U28: =_xlfn.RANK.EQ(T28,$T$7:$T$592,0) -> 383
C29: Nippon India Large Cap Fund | D29: 5 | E29: Unlock | F29: Equity: Large Cap | G29: 3.05 | H29: -3.29 | I29: 16.16 | J29: 7.34 | K29: 17.08 | L29: 12.88 | M29: 2.08 | N29: Very High | O29: Above Avg. | P29: Direct | Q29: =I29*0.4+K29*0.5 -> 15.004 | R29: =(L29+J29)/2 -> 10.11 | S29: =(M29+K29)/2 -> 9.58 | T29: =('Investor-Inputs'!$G$19 * Q29) + ('Investor-Inputs'!$J$19 * R29) + ('Investor-Inputs'!$N$19 * S29) -> 74.812 | U29: =_xlfn.RANK.EQ(T29,$T$7:$T$592,0) -> 162
C30: Nippon India Nifty Next 50 Junior BeES FoF - Regular Plan | D30: 4 | E30: Unlock | F30: Equity: Large Cap | G30: 9.02 | H30: 7.57 | I30: 21.18 | J30: 11.12 | K30: 15.23 | L30: 13.65 | M30: 0.3 | N30: Very High | O30: High | P30: Direct | Q30: =I30*0.4+K30*0.5 -> 16.087 | R30: =(L30+J30)/2 -> 12.385 | S30: =(M30+K30)/2 -> 7.765 | T30: =('Investor-Inputs'!$G$19 * Q30) + ('Investor-Inputs'!$J$19 * R30) + ('Investor-Inputs'!$N$19 * S30) -> 80.796 | U30: =_xlfn.RANK.EQ(T30,$T$7:$T$592,0) -> 130
C31: SBI Large Cap Fund | D31: 4 | E31: Unlock | F31: Equity: Large Cap | G31: 2.32 | H31: -2.17 | I31: 12.03 | J31: 6.1 | K31: 12.24 | L31: 9.46 | M31: 1.47 | N31: Very High | O31: Avg. | P31: Direct | Q31: =I31*0.4+K31*0.5 -> 10.932 | R31: =(L31+J31)/2 -> 7.78 | S31: =(M31+K31)/2 -> 6.855 | T31: =('Investor-Inputs'!$G$19 * Q31) + ('Investor-Inputs'!$J$19 * R31) + ('Investor-Inputs'!$N$19 * S31) -> 55.211 | U31: =_xlfn.RANK.EQ(T31,$T$7:$T$592,0) -> 268
C32: SBI Nifty Next 50 Index Fund - Regular Plan | D32: 5 | E32: Unlock | F32: Equity: Large Cap | G32: 8.24 | H32: 6.83 | I32: 20.71 | J32: 10.59 | M32: 0.71 | N32: Very High | O32: High | P32: Direct | Q32: =I32*0.4+K32*0.5 -> 8.284 | R32: =(L32+J32)/2 -> 5.295 | S32: =(M32+K32)/2 -> 0.355 | T32: =('Investor-Inputs'!$G$19 * Q32) + ('Investor-Inputs'!$J$19 * R32) + ('Investor-Inputs'!$N$19 * S32) -> 35.797 | U32: =_xlfn.RANK.EQ(T32,$T$7:$T$592,0) -> 359
C33: Sundaram Nifty 100 Equal Weight Fund | D33: 4 | E33: Unlock | F33: Equity: Large Cap | G33: 7.83 | H33: 5.02 | I33: 17.79 | J33: 9.55 | K33: 14.25 | L33: 12.35 | M33: 1.06 | N33: Very High | O33: Above Avg. | P33: Direct | Q33: =I33*0.4+K33*0.5 -> 14.241 | R33: =(L33+J33)/2 -> 10.95 | S33: =(M33+K33)/2 -> 7.655 | T33: =('Investor-Inputs'!$G$19 * Q33) + ('Investor-Inputs'!$J$19 * R33) + ('Investor-Inputs'!$N$19 * S33) -> 72.278 | U33: =_xlfn.RANK.EQ(T33,$T$7:$T$592,0) -> 182
C34: Tata Large Cap Fund - Regular Plan | D34: 4 | E34: Unlock | F34: Equity: Large Cap | G34: 2.52 | H34: -1.62 | I34: 13.25 | J34: 6.04 | K34: 12.53 | L34: 9.59 | M34: 2.33 | N34: Very High | O34: Above Avg. | P34: Direct | Q34: =I34*0.4+K34*0.5 -> 11.565 | R34: =(L34+J34)/2 -> 7.815 | S34: =(M34+K34)/2 -> 7.43 | T34: =('Investor-Inputs'!$G$19 * Q34) + ('Investor-Inputs'!$J$19 * R34) + ('Investor-Inputs'!$N$19 * S34) -> 57.755 | U34: =_xlfn.RANK.EQ(T34,$T$7:$T$592,0) -> 244
C35: WhiteOak Capital Large Cap Fund - Regular Plan | D35: 4 | E35: Unlock | F35: Equity: Large Cap | G35: 1.28 | H35: -4.43 | I35: 15.01 | J35: 7.07 | M35: 2.63 | N35: Very High | O35: Above Avg. | P35: Direct | Q35: =I35*0.4+K35*0.5 -> 6.004 | R35: =(L35+J35)/2 -> 3.535 | S35: =(M35+K35)/2 -> 1.315 | T35: =('Investor-Inputs'!$G$19 * Q35) + ('Investor-Inputs'!$J$19 * R35) + ('Investor-Inputs'!$N$19 * S35) -> 26.397 | U35: =_xlfn.RANK.EQ(T35,$T$7:$T$592,0) -> 566
C36: Bandhan Large & Mid Cap Fund - Regular Plan | D36: 5 | E36: Unlock | F36: Equity: Large & MidCap | G36: 9.77 | H36: 5.76 | I36: 23.13 | J36: 13.09 | K36: 19.12 | L36: 17.22 | M36: 2.9 | N36: Very High | O36: High | P36: Direct | Q36: =I36*0.4+K36*0.5 -> 18.812 | R36: =(L36+J36)/2 -> 15.155 | S36: =(M36+K36)/2 -> 11.01 | T36: =('Investor-Inputs'!$G$19 * Q36) + ('Investor-Inputs'!$J$19 * R36) + ('Investor-Inputs'!$N$19 * S36) -> 97.756 | U36: =_xlfn.RANK.EQ(T36,$T$7:$T$592,0) -> 53
C37: DSP Large & Mid Cap Fund - Regular Plan | D37: 4 | E37: Unlock | F37: Equity: Large & MidCap | G37: 1.71 | H37: -3 | I37: 18.4 | J37: 8.3 | K37: 15.02 | L37: 12.74 | M37: 2.12 | N37: Very High | O37: Above Avg. | P37: Direct | Q37: =I37*0.4+K37*0.5 -> 14.87 | R37: =(L37+J37)/2 -> 10.52 | S37: =(M37+K37)/2 -> 8.57 | T37: =('Investor-Inputs'!$G$19 * Q37) + ('Investor-Inputs'!$J$19 * R37) + ('Investor-Inputs'!$N$19 * S37) -> 74.22 | U37: =_xlfn.RANK.EQ(T37,$T$7:$T$592,0) -> 166
C38: HDFC Large and Mid Cap Fund - Regular Plan | D38: 4 | E38: Unlock | F38: Equity: Large & MidCap | G38: 3.83 | H38: -2.27 | I38: 17.9 | J38: 7.49 | K38: 17.56 | L38: 13.3 | M38: 1.59 | N38: Very High | O38: Above Avg. | P38: Direct | Q38: =I38*0.4+K38*0.5 -> 15.94 | R38: =(L38+J38)/2 -> 10.395 | S38: =(M38+K38)/2 -> 9.575 | T38: =('Investor-Inputs'!$G$19 * Q38) + ('Investor-Inputs'!$J$19 * R38) + ('Investor-Inputs'!$N$19 * S38) -> 78.185 | U38: =_xlfn.RANK.EQ(T38,$T$7:$T$592,0) -> 142
C39: ICICI Prudential Large & Mid Cap Fund | D39: 5 | E39: Unlock | F39: Equity: Large & MidCap | G39: 4.76 | H39: -0.1 | I39: 19.51 | J39: 10.55 | K39: 19.35 | L39: 15.25 | M39: 2.32 | N39: Very High | O39: Above Avg. | P39: Direct | Q39: =I39*0.4+K39*0.5 -> 17.479 | R39: =(L39+J39)/2 -> 12.9 | S39: =(M39+K39)/2 -> 10.835 | T39: =('Investor-Inputs'!$G$19 * Q39) + ('Investor-Inputs'!$J$19 * R39) + ('Investor-Inputs'!$N$19 * S39) -> 89.072 | U39: =_xlfn.RANK.EQ(T39,$T$7:$T$592,0) -> 83
C40: Invesco India Large & Mid Cap Fund - Regular Plan | D40: 4 | E40: Unlock | F40: Equity: Large & MidCap | G40: 8.69 | H40: 0.98 | I40: 23.14 | J40: 13.51 | K40: 17.71 | L40: 16.59 | M40: 1.9 | N40: Very High | O40: High | P40: Direct | Q40: =I40*0.4+K40*0.5 -> 18.111 | R40: =(L40+J40)/2 -> 15.05 | S40: =(M40+K40)/2 -> 9.805 | T40: =('Investor-Inputs'!$G$19 * Q40) + ('Investor-Inputs'!$J$19 * R40) + ('Investor-Inputs'!$N$19 * S40) -> 94.238 | U40: =_xlfn.RANK.EQ(T40,$T$7:$T$592,0) -> 61
C41: Motilal Oswal Large and Midcap Fund - Regular Plan | D41: 4 | E41: Unlock | F41: Equity: Large & MidCap | G41: 15.63 | H41: 9.31 | I41: 25.52 | J41: 15.88 | K41: 20.97 | L41: 19.38 | M41: 1.91 | N41: Very High | O41: High | P41: Direct | Q41: =I41*0.4+K41*0.5 -> 20.693 | R41: =(L41+J41)/2 -> 17.63 | S41: =(M41+K41)/2 -> 11.44 | T41: =('Investor-Inputs'!$G$19 * Q41) + ('Investor-Inputs'!$J$19 * R41) + ('Investor-Inputs'!$N$19 * S41) -> 108.779 | U41: =_xlfn.RANK.EQ(T41,$T$7:$T$592,0) -> 35
C42: Nippon India Vision Large & Mid Cap Fund | D42: 4 | E42: Unlock | F42: Equity: Large & MidCap | G42: 3.77 | H42: -0.43 | I42: 19.32 | J42: 9.72 | K42: 16.65 | L42: 13.98 | M42: 1.8 | N42: Very High | O42: Above Avg. | P42: Direct | Q42: =I42*0.4+K42*0.5 -> 16.053 | R42: =(L42+J42)/2 -> 11.85 | S42: =(M42+K42)/2 -> 9.225 | T42: =('Investor-Inputs'!$G$19 * Q42) + ('Investor-Inputs'!$J$19 * R42) + ('Investor-Inputs'!$N$19 * S42) -> 81.084 | U42: =_xlfn.RANK.EQ(T42,$T$7:$T$592,0) -> 124
C43: SBI Large & Midcap Fund | D43: 4 | E43: Unlock | F43: Equity: Large & MidCap | G43: 7.36 | H43: 1 | I43: 16.09 | J43: 9.1 | K43: 16.53 | L43: 12.82 | M43: 1.72 | N43: Very High | O43: Avg. | P43: Direct | Q43: =I43*0.4+K43*0.5 -> 14.701 | R43: =(L43+J43)/2 -> 10.96 | S43: =(M43+K43)/2 -> 9.125 | T43: =('Investor-Inputs'!$G$19 * Q43) + ('Investor-Inputs'!$J$19 * R43) + ('Investor-Inputs'!$N$19 * S43) -> 75.148 | U43: =_xlfn.RANK.EQ(T43,$T$7:$T$592,0) -> 156
C44: UTI Large & Mid Cap Fund - Regular Plan | D44: 5 | E44: Unlock | F44: Equity: Large & MidCap | G44: 6.37 | H44: 2.1 | I44: 20.12 | J44: 10.84 | K44: 17.61 | L44: 15.01 | M44: 1.85 | N44: Very High | O44: Above Avg. | P44: Direct | Q44: =I44*0.4+K44*0.5 -> 16.853 | R44: =(L44+J44)/2 -> 12.925 | S44: =(M44+K44)/2 -> 9.73 | T44: =('Investor-Inputs'!$G$19 * Q44) + ('Investor-Inputs'!$J$19 * R44) + ('Investor-Inputs'!$N$19 * S44) -> 86.139 | U44: =_xlfn.RANK.EQ(T44,$T$7:$T$592,0) -> 106
C45: Aditya Birla Sun Life Flexi Cap Fund - Regular Plan | D45: 4 | E45: Unlock | F45: Equity: Flexi Cap | G45: 6.66 | H45: 2.86 | I45: 17.36 | J45: 10.21 | K45: 13.7 | L45: 12.34 | M45: 1.6 | N45: Very High | O45: Above Avg. | P45: Direct | Q45: =I45*0.4+K45*0.5 -> 13.794 | R45: =(L45+J45)/2 -> 11.275 | S45: =(M45+K45)/2 -> 7.65 | T45: =('Investor-Inputs'!$G$19 * Q45) + ('Investor-Inputs'!$J$19 * R45) + ('Investor-Inputs'!$N$19 * S45) -> 71.582 | U45: =_xlfn.RANK.EQ(T45,$T$7:$T$592,0) -> 186
...

Sheet mf_charts
C6: Fund Name | D6: Rating | E6: VR Opinion | F6: Category | G6: 1 Year Returns (%) | H6: 1 Year SIP Returns (%) | I6: 3 Year Returns (%) | J6: 3 Year SIP Returns (%) | K6: 5 Year Returns (%) | L6: 5 Year SIP Returns (%) | M6: Expense Ratio (%) | N6: Riskometer | O6: Return Grade | P6: Plan | Q6: ReturnScore | R6: SIPScore | S6: CostScore | T6: MFScore | U6: Rank
C7: Aditya Birla Sun Life Large Cap Fund - Regular Plan | D7: 4 | E7: Unlock | F7: Equity: Large Cap | G7: -0.47 | H7: -6.31 | I7: 13.07 | J7: 5.14 | K7: 12.5 | L7: 9.15 | M7: 1.58 | N7: Very High | O7: Above Avg. | P7: Direct | Q7: =I7*0.4+K7*0.5 -> 11.478 | R7: =(L7+J7)/2 -> 7.145 | S7: =(M7+K7)/2 -> 7.04 | T7: =('Investor-Inputs'!$G$19 * Q7) + ('Investor-Inputs'!$J$19 * R7) + ('Investor-Inputs'!$N$19 * S7) -> 55.764 | U7: =_xlfn.RANK.EQ(T7,$T$7:$T$592,0) -> 256
C8: Aditya Birla Sun Life Nifty 50 Equal Weight Index Fund - Regular Plan | D8: 4 | E8: Unlock | F8: Equity: Large Cap | G8: 6.69 | H8: 2.58 | I8: 15.81 | J8: 8.65 | M8: 1.1 | N8: Very High | O8: Above Avg. | P8: Direct | Q8: =I8*0.4+K8*0.5 -> 6.324 | R8: =(L8+J8)/2 -> 4.325 | S8: =(M8+K8)/2 -> 0.55 | T8: =('Investor-Inputs'!$G$19 * Q8) + ('Investor-Inputs'!$J$19 * R8) + ('Investor-Inputs'!$N$19 * S8) -> 28.172 | U8: =_xlfn.RANK.EQ(T8,$T$7:$T$592,0) -> 554
C9: Aditya Birla Sun Life Nifty Next 50 Index Fund - Regular Plan | D9: 4 | E9: Unlock | F9: Equity: Large Cap | G9: 8.12 | H9: 6.8 | I9: 20.35 | J9: 10.29 | M9: 0.89 | N9: Very High | O9: Above Avg. | P9: Direct | Q9: =I9*0.4+K9*0.5 -> 8.14 | R9: =(L9+J9)/2 -> 5.145 | S9: =(M9+K9)/2 -> 0.445 | T9: =('Investor-Inputs'!$G$19 * Q9) + ('Investor-Inputs'!$J$19 * R9) + ('Investor-Inputs'!$N$19 * S9) -> 35.155 | U9: =_xlfn.RANK.EQ(T9,$T$7:$T$592,0) -> 389
C10: Bandhan Large Cap Fund - Regular Plan | D10: 4 | E10: Unlock | F10: Equity: Large Cap | G10: 2.79 | H10: -2.89 | I10: 14.78 | J10: 7.14 | K10: 12.89 | L10: 10.4 | M10: 2.24 | N10: Very High | O10: Above Avg. | P10: Direct | Q10: =I10*0.4+K10*0.5 -> 12.357 | R10: =(L10+J10)/2 -> 8.77 | S10: =(M10+K10)/2 -> 7.565 | T10: =('Investor-Inputs'!$G$19 * Q10) + ('Investor-Inputs'!$J$19 * R10) + ('Investor-Inputs'!$N$19 * S10) -> 62.176 | U10: =_xlfn.RANK.EQ(T10,$T$7:$T$592,0) -> 226
C11: Baroda BNP Paribas Large Cap Fund - Regular Plan | D11: 4 | E11: Unlock | F11: Equity: Large Cap | G11: 2.57 | H11: -0.27 | I11: 14.44 | J11: 6.72 | K11: 13.07 | L11: 10.53 | M11: 2 | N11: Very High | O11: Above Avg. | P11: Direct | Q11: =I11*0.4+K11*0.5 -> 12.311 | R11: =(L11+J11)/2 -> 8.625 | S11: =(M11+K11)/2 -> 7.535 | T11: =('Investor-Inputs'!$G$19 * Q11) + ('Investor-Inputs'!$J$19 * R11) + ('Investor-Inputs'!$N$19 * S11) -> 61.718 | U11: =_xlfn.RANK.EQ(T11,$T$7:$T$592,0) -> 230
C12: Canara Robeco Large Cap Fund - Regular Plan | D12: 4 | E12: Unlock | F12: Equity: Large Cap | G12: -1.43 | H12: -6.93 | I12: 12.6 | J12: 4.99 | K12: 11.37 | L12: 8.71 | M12: 1.75 | N12: Very High | O12: Avg. | P12: Direct | Q12: =I12*0.4+K12*0.5 -> 10.725 | R12: =(L12+J12)/2 -> 6.85 | S12: =(M12+K12)/2 -> 6.56 | T12: =('Investor-Inputs'!$G$19 * Q12) + ('Investor-Inputs'!$J$19 * R12) + ('Investor-Inputs'!$N$19 * S12) -> 52.435 | U12: =_xlfn.RANK.EQ(T12,$T$7:$T$592,0) -> 275
C13: DSP Large Cap Fund - Regular Plan | D13: 5 | E13: Unlock | F13: Equity: Large Cap | G13: -2.41 | H13: -6.84 | I13: 15.09 | J13: 6.23 | K13: 12.28 | L13: 10.35 | M13: 2.52 | N13: Very High | O13: Above Avg. | P13: Direct | Q13: =I13*0.4+K13*0.5 -> 12.176 | R13: =(L13+J13)/2 -> 8.29 | S13: =(M13+K13)/2 -> 7.4 | T13: =('Investor-Inputs'!$G$19 * Q13) + ('Investor-Inputs'!$J$19 * R13) + ('Investor-Inputs'!$N$19 * S13) -> 60.508 | U13: =_xlfn.RANK.EQ(T13,$T$7:$T$592,0) -> 236
C14: DSP Nifty 50 Equal Weight Index Fund - Regular Plan | D14: 5 | E14: Unlock | F14: Equity: Large Cap | G14: 6.81 | H14: 2.67 | I14: 15.95 | J14: 8.77 | K14: 14.83 | L14: 12.24 | M14: 0.95 | N14: Very High | O14: Above Avg. | P14: Direct | Q14: =I14*0.4+K14*0.5 -> 13.795 | R14: =(L14+J14)/2 -> 10.505 | S14: =(M14+K14)/2 -> 7.89 | T14: =('Investor-Inputs'!$G$19 * Q14) + ('Investor-Inputs'!$J$19 * R14) + ('Investor-Inputs'!$N$19 * S14) -> 70.285 | U14: =_xlfn.RANK.EQ(T14,$T$7:$T$592,0) -> 192
C15: DSP Nifty Next 50 Index Fund - Regular Plan | D15: 4 | E15: Unlock | F15: Equity: Large Cap | G15: 8.35 | H15: 6.86 | I15: 20.83 | J15: 10.65 | K15: 15.1 | L15: 13.33 | M15: 0.98 | N15: Very High | O15: High | P15: Direct | Q15: =I15*0.4+K15*0.5 -> 15.882 | R15: =(L15+J15)/2 -> 11.99 | S15: =(M15+K15)/2 -> 8.04 | T15: =('Investor-Inputs'!$G$19 * Q15) + ('Investor-Inputs'!$J$19 * R15) + ('Investor-Inputs'!$N$19 * S15) -> 79.666 | U15: =_xlfn.RANK.EQ(T15,$T$7:$T$592,0) -> 132
C16: Edelweiss Large Cap Fund - Regular Plan | D16: 4 | E16: Unlock | F16: Equity: Large Cap | G16: -0.09 | H16: -5.13 | I16: 12.29 | J16: 4.59 | K16: 12.11 | L16: 9 | M16: 2.12 | N16: Very High | O16: Avg. | P16: Direct | Q16: =I16*0.4+K16*0.5 -> 10.971 | R16: =(L16+J16)/2 -> 6.795 | S16: =(M16+K16)/2 -> 7.115 | T16: =('Investor-Inputs'!$G$19 * Q16) + ('Investor-Inputs'!$J$19 * R16) + ('Investor-Inputs'!$N$19 * S16) -> 53.618 | U16: =_xlfn.RANK.EQ(T16,$T$7:$T$592,0) -> 273
C17: HDFC Large Cap Fund - Regular Plan | D17: 5 | E17: Unlock | F17: Equity: Large Cap | G17: -1.59 | H17: -6.6 | I17: 12.48 | J17: 3.95 | K17: 13.84 | L17: 9.59 | M17: 1.58 | N17: Very High | O17: Above Avg. | P17: Direct | Q17: =I17*0.4+K17*0.5 -> 11.912 | R17: =(L17+J17)/2 -> 6.77 | S17: =(M17+K17)/2 -> 7.71 | T17: =('Investor-Inputs'!$G$19 * Q17) + ('Investor-Inputs'!$J$19 * R17) + ('Investor-Inputs'!$N$19 * S17) -> 56.986 | U17: =_xlfn.RANK.EQ(T17,$T$7:$T$592,0) -> 246
C18: HDFC NIFTY 100 Equal Weight Index Fund - Regular Plan | D18: 4 | E18: Unlock | F18: Equity: Large Cap | G18: 7.88 | H18: 4.9 | I18: 18.08 | J18: 9.68 | M18: 0.88 | N18: Very High | O18: Above Avg. | P18: Direct | Q18: =I18*0.4+K18*0.5 -> 7.232 | R18: =(L18+J18)/2 -> 4.84 | S18: =(M18+K18)/2 -> 0.44 | T18: =('Investor-Inputs'!$G$19 * Q18) + ('Investor-Inputs'!$J$19 * R18) + ('Investor-Inputs'!$N$19 * S18) -> 31.816 | U18: =_xlfn.RANK.EQ(T18,$T$7:$T$592,0) -> 504
C19: HDFC NIFTY50 Equal Weight Index Fund - Regular Plan | D19: 5 | E19: Unlock | F19: Equity: Large Cap | G19: 6.85 | H19: 2.71 | I19: 16.02 | J19: 8.85 | M19: 1 | N19: Very High | O19: Above Avg. | P19: Direct | Q19: =I19*0.4+K19*0.5 -> 6.408 | R19: =(L19+J19)/2 -> 4.425 | S19: =(M19+K19)/2 -> 0.5 | T19: =('Investor-Inputs'!$G$19 * Q19) + ('Investor-Inputs'!$J$19 * R19) + ('Investor-Inputs'!$N$19 * S19) -> 28.574 | U19: =_xlfn.RANK.EQ(T19,$T$7:$T$592,0) -> 546
C20: ICICI Prudential BHARAT 22 FOF | D20: 5 | E20: Unlock | F20: Equity: Large Cap | G20: 17.4 | H20: 18.98 | I20: 25.53 | J20: 16.37 | K20: 28 | L20: 23.73 | M20: 0.14 | N20: Very High | O20: High | P20: Direct | Q20: =I20*0.4+K20*0.5 -> 24.212 | R20: =(L20+J20)/2 -> 20.05 | S20: =(M20+K20)/2 -> 14.07 | T20: =('Investor-Inputs'!$G$19 * Q20) + ('Investor-Inputs'!$J$19 * R20) + ('Investor-Inputs'!$N$19 * S20) -> 126.806 | U20: =_xlfn.RANK.EQ(T20,$T$7:$T$592,0) -> 7
C21: ICICI Prudential Large Cap Fund | D21: 5 | E21: Unlock | F21: Equity: Large Cap | G21: 0.07 | H21: -5.94 | I21: 15.26 | J21: 6.51 | K21: 14.67 | L21: 11.25 | M21: 3.59 | N21: Very High | O21: Above Avg. | P21: Direct | Q21: =I21*0.4+K21*0.5 -> 13.439 | R21: =(L21+J21)/2 -> 8.88 | S21: =(M21+K21)/2 -> 9.13 | T21: =('Investor-Inputs'!$G$19 * Q21) + ('Investor-Inputs'!$J$19 * R21) + ('Investor-Inputs'!$N$19 * S21) -> 67.207 | U21: =_xlfn.RANK.EQ(T21,$T$7:$T$592,0) -> 202
C22: ICICI Prudential Nifty 100 Low Volatility 30 ETF FOF | D22: 4 | E22: Unlock | F22: Equity: Large Cap | G22: 1.08 | H22: -4.13 | I22: 13.56 | J22: 5.49 | K22: 12.11 | L22: 9.43 | M22: 0.58 | N22: Very High | O22: Avg. | P22: Direct | Q22: =I22*0.4+K22*0.5 -> 11.479 | R22: =(L22+J22)/2 -> 7.46 | S22: =(M22+K22)/2 -> 6.345 | T22: =('Investor-Inputs'!$G$19 * Q22) + ('Investor-Inputs'!$J$19 * R22) + ('Investor-Inputs'!$N$19 * S22) -> 55.702 | U22: =_xlfn.RANK.EQ(T22,$T$7:$T$592,0) -> 258
C23: ICICI Prudential Nifty50 Equal Weight Index Fund | D23: 4 | E23: Unlock | F23: Equity: Large Cap | G23: 6.65 | H23: 2.53 | I23: 15.8 | J23: 8.67 | M23: 1.25 | N23: Very High | O23: Above Avg. | P23: Direct | Q23: =I23*0.4+K23*0.5 -> 6.32 | R23: =(L23+J23)/2 -> 4.335 | S23: =(M23+K23)/2 -> 0.625 | T23: =('Investor-Inputs'!$G$19 * Q23) + ('Investor-Inputs'!$J$19 * R23) + ('Investor-Inputs'!$N$19 * S23) -> 28.255 | U23: =_xlfn.RANK.EQ(T23,$T$7:$T$592,0) -> 552
C24: Invesco India Largecap Fund - Regular Plan | D24: 4 | E24: Unlock | F24: Equity: Large Cap | G24: 2.12 | H24: -3.12 | I24: 15.53 | J24: 7 | K24: 13.55 | L24: 10.5 | M24: 2.08 | N24: Very High | O24: Above Avg. | P24: Direct | Q24: =I24*0.4+K24*0.5 -> 12.987 | R24: =(L24+J24)/2 -> 8.75 | S24: =(M24+K24)/2 -> 7.815 | T24: =('Investor-Inputs'!$G$19 * Q24) + ('Investor-Inputs'!$J$19 * R24) + ('Investor-Inputs'!$N$19 * S24) -> 64.276 | U24: =_xlfn.RANK.EQ(T24,$T$7:$T$592,0) -> 212
C25: Kotak Large Cap Fund - Regular Plan | D25: 4 | E25: Unlock | F25: Equity: Large Cap | G25: 0.86 | H25: -5.19 | I25: 12.92 | J25: 5.64 | K25: 12.12 | L25: 9.24 | M25: 1.89 | N25: Very High | O25: Avg. | P25: Direct | Q25: =I25*0.4+K25*0.5 -> 11.228 | R25: =(L25+J25)/2 -> 7.44 | S25: =(M25+K25)/2 -> 7.005 | T25: =('Investor-Inputs'!$G$19 * Q25) + ('Investor-Inputs'!$J$19 * R25) + ('Investor-Inputs'!$N$19 * S25) -> 55.569 | U25: =_xlfn.RANK.EQ(T25,$T$7:$T$592,0) -> 262
C26: Kotak Nifty Next 50 Index Fund - Regular Plan | D26: 4 | E26: Unlock | F26: Equity: Large Cap | G26: 8.33 | H26: 6.98 | I26: 20.72 | J26: 10.66 | K26: 15.03 | L26: 13.29 | M26: 0.9 | N26: Very High | O26: High | P26: Direct | Q26: =I26*0.4+K26*0.5 -> 15.803 | R26: =(L26+J26)/2 -> 11.975 | S26: =(M26+K26)/2 -> 7.965 | T26: =('Investor-Inputs'!$G$19 * Q26) + ('Investor-Inputs'!$J$19 * R26) + ('Investor-Inputs'!$N$19 * S26) -> 79.324 | U26: =_xlfn.RANK.EQ(T26,$T$7:$T$592,0) -> 134
C27: Mirae Asset Diversified Equity Allocator Passive FoF - Regular Plan | D27: 4 | E27: Unlock | F27: Equity: Large Cap | G27: 3.38 | H27: -1.33 | I27: 14.48 | J27: 6.77 | K27: 13.29 | L27: 10.45 | M27: 0.11 | N27: Very High | O27: Above Avg. | P27: Direct | Q27: =I27*0.4+K27*0.5 -> 12.437 | R27: =(L27+J27)/2 -> 8.61 | S27: =(M27+K27)/2 -> 6.7 | T27: =('Investor-Inputs'!$G$19 * Q27) + ('Investor-Inputs'!$J$19 * R27) + ('Investor-Inputs'!$N$19 * S27) -> 61.231 | U27: =_xlfn.RANK.EQ(T27,$T$7:$T$592,0) -> 232
C28: Navi Nifty Next 50 Index Fund - Regular Plan | D28: 4 | E28: Unlock | F28: Equity: Large Cap | G28: 7.86 | H28: 6.38 | I28: 20.48 | J28: 10.34 | M28: 1.07 | N28: Very High | O28: Above Avg. | P28: Direct | Q28: =I28*0.4+K28*0.5 -> 8.192 | R28: =(L28+J28)/2 -> 5.17 | S28: =(M28+K28)/2 -> 0.535 | T28: =('Investor-Inputs'!$G$19 * Q28) + ('Investor-Inputs'!$J$19 * R28) + ('Investor-Inputs'!$N$19 * S28) -> 35.451 | U28: =_xlfn.RANK.EQ(T28,$T$7:$T$592,0) -> 383
C29: Nippon India Large Cap Fund | D29: 5 | E29: Unlock | F29: Equity: Large Cap | G29: 3.05 | H29: -3.29 | I29: 16.16 | J29: 7.34 | K29: 17.08 | L29: 12.88 | M29: 2.08 | N29: Very High | O29: Above Avg. | P29: Direct | Q29: =I29*0.4+K29*0.5 -> 15.004 | R29: =(L29+J29)/2 -> 10.11 | S29: =(M29+K29)/2 -> 9.58 | T29: =('Investor-Inputs'!$G$19 * Q29) + ('Investor-Inputs'!$J$19 * R29) + ('Investor-Inputs'!$N$19 * S29) -> 74.812 | U29: =_xlfn.RANK.EQ(T29,$T$7:$T$592,0) -> 162
C30: Nippon India Nifty Next 50 Junior BeES FoF - Regular Plan | D30: 4 | E30: Unlock | F30: Equity: Large Cap | G30: 9.02 | H30: 7.57 | I30: 21.18 | J30: 11.12 | K30: 15.23 | L30: 13.65 | M30: 0.3 | N30: Very High | O30: High | P30: Direct | Q30: =I30*0.4+K30*0.5 -> 16.087 | R30: =(L30+J30)/2 -> 12.385 | S30: =(M30+K30)/2 -> 7.765 | T30: =('Investor-Inputs'!$G$19 * Q30) + ('Investor-Inputs'!$J$19 * R30) + ('Investor-Inputs'!$N$19 * S30) -> 80.796 | U30: =_xlfn.RANK.EQ(T30,$T$7:$T$592,0) -> 130
C31: SBI Large Cap Fund | D31: 4 | E31: Unlock | F31: Equity: Large Cap | G31: 2.32 | H31: -2.17 | I31: 12.03 | J31: 6.1 | K31: 12.24 | L31: 9.46 | M31: 1.47 | N31: Very High | O31: Avg. | P31: Direct | Q31: =I31*0.4+K31*0.5 -> 10.932 | R31: =(L31+J31)/2 -> 7.78 | S31: =(M31+K31)/2 -> 6.855 | T31: =('Investor-Inputs'!$G$19 * Q31) + ('Investor-Inputs'!$J$19 * R31) + ('Investor-Inputs'!$N$19 * S31) -> 55.211 | U31: =_xlfn.RANK.EQ(T31,$T$7:$T$592,0) -> 268
C32: SBI Nifty Next 50 Index Fund - Regular Plan | D32: 5 | E32: Unlock | F32: Equity: Large Cap | G32: 8.24 | H32: 6.83 | I32: 20.71 | J32: 10.59 | M32: 0.71 | N32: Very High | O32: High | P32: Direct | Q32: =I32*0.4+K32*0.5 -> 8.284 | R32: =(L32+J32)/2 -> 5.295 | S32: =(M32+K32)/2 -> 0.355 | T32: =('Investor-Inputs'!$G$19 * Q32) + ('Investor-Inputs'!$J$19 * R32) + ('Investor-Inputs'!$N$19 * S32) -> 35.797 | U32: =_xlfn.RANK.EQ(T32,$T$7:$T$592,0) -> 359
C33: Sundaram Nifty 100 Equal Weight Fund | D33: 4 | E33: Unlock | F33: Equity: Large Cap | G33: 7.83 | H33: 5.02 | I33: 17.79 | J33: 9.55 | K33: 14.25 | L33: 12.35 | M33: 1.06 | N33: Very High | O33: Above Avg. | P33: Direct | Q33: =I33*0.4+K33*0.5 -> 14.241 | R33: =(L33+J33)/2 -> 10.95 | S33: =(M33+K33)/2 -> 7.655 | T33: =('Investor-Inputs'!$G$19 * Q33) + ('Investor-Inputs'!$J$19 * R33) + ('Investor-Inputs'!$N$19 * S33) -> 72.278 | U33: =_xlfn.RANK.EQ(T33,$T$7:$T$592,0) -> 182
C34: Tata Large Cap Fund - Regular Plan | D34: 4 | E34: Unlock | F34: Equity: Large Cap | G34: 2.52 | H34: -1.62 | I34: 13.25 | J34: 6.04 | K34: 12.53 | L34: 9.59 | M34: 2.33 | N34: Very High | O34: Above Avg. | P34: Direct | Q34: =I34*0.4+K34*0.5 -> 11.565 | R34: =(L34+J34)/2 -> 7.815 | S34: =(M34+K34)/2 -> 7.43 | T34: =('Investor-Inputs'!$G$19 * Q34) + ('Investor-Inputs'!$J$19 * R34) + ('Investor-Inputs'!$N$19 * S34) -> 57.755 | U34: =_xlfn.RANK.EQ(T34,$T$7:$T$592,0) -> 244
C35: WhiteOak Capital Large Cap Fund - Regular Plan | D35: 4 | E35: Unlock | F35: Equity: Large Cap | G35: 1.28 | H35: -4.43 | I35: 15.01 | J35: 7.07 | M35: 2.63 | N35: Very High | O35: Above Avg. | P35: Direct | Q35: =I35*0.4+K35*0.5 -> 6.004 | R35: =(L35+J35)/2 -> 3.535 | S35: =(M35+K35)/2 -> 1.315 | T35: =('Investor-Inputs'!$G$19 * Q35) + ('Investor-Inputs'!$J$19 * R35) + ('Investor-Inputs'!$N$19 * S35) -> 26.397 | U35: =_xlfn.RANK.EQ(T35,$T$7:$T$592,0) -> 566
C36: Bandhan Large & Mid Cap Fund - Regular Plan | D36: 5 | E36: Unlock | F36: Equity: Large & MidCap | G36: 9.77 | H36: 5.76 | I36: 23.13 | J36: 13.09 | K36: 19.12 | L36: 17.22 | M36: 2.9 | N36: Very High | O36: High | P36: Direct | Q36: =I36*0.4+K36*0.5 -> 18.812 | R36: =(L36+J36)/2 -> 15.155 | S36: =(M36+K36)/2 -> 11.01 | T36: =('Investor-Inputs'!$G$19 * Q36) + ('Investor-Inputs'!$J$19 * R36) + ('Investor-Inputs'!$N$19 * S36) -> 97.756 | U36: =_xlfn.RANK.EQ(T36,$T$7:$T$592,0) -> 53
C37: DSP Large & Mid Cap Fund - Regular Plan | D37: 4 | E37: Unlock | F37: Equity: Large & MidCap | G37: 1.71 | H37: -3 | I37: 18.4 | J37: 8.3 | K37: 15.02 | L37: 12.74 | M37: 2.12 | N37: Very High | O37: Above Avg. | P37: Direct | Q37: =I37*0.4+K37*0.5 -> 14.87 | R37: =(L37+J37)/2 -> 10.52 | S37: =(M37+K37)/2 -> 8.57 | T37: =('Investor-Inputs'!$G$19 * Q37) + ('Investor-Inputs'!$J$19 * R37) + ('Investor-Inputs'!$N$19 * S37) -> 74.22 | U37: =_xlfn.RANK.EQ(T37,$T$7:$T$592,0) -> 166
C38: HDFC Large and Mid Cap Fund - Regular Plan | D38: 4 | E38: Unlock | F38: Equity: Large & MidCap | G38: 3.83 | H38: -2.27 | I38: 17.9 | J38: 7.49 | K38: 17.56 | L38: 13.3 | M38: 1.59 | N38: Very High | O38: Above Avg. | P38: Direct | Q38: =I38*0.4+K38*0.5 -> 15.94 | R38: =(L38+J38)/2 -> 10.395 | S38: =(M38+K38)/2 -> 9.575 | T38: =('Investor-Inputs'!$G$19 * Q38) + ('Investor-Inputs'!$J$19 * R38) + ('Investor-Inputs'!$N$19 * S38) -> 78.185 | U38: =_xlfn.RANK.EQ(T38,$T$7:$T$592,0) -> 142
C39: ICICI Prudential Large & Mid Cap Fund | D39: 5 | E39: Unlock | F39: Equity: Large & MidCap | G39: 4.76 | H39: -0.1 | I39: 19.51 | J39: 10.55 | K39: 19.35 | L39: 15.25 | M39: 2.32 | N39: Very High | O39: Above Avg. | P39: Direct | Q39: =I39*0.4+K39*0.5 -> 17.479 | R39: =(L39+J39)/2 -> 12.9 | S39: =(M39+K39)/2 -> 10.835 | T39: =('Investor-Inputs'!$G$19 * Q39) + ('Investor-Inputs'!$J$19 * R39) + ('Investor-Inputs'!$N$19 * S39) -> 89.072 | U39: =_xlfn.RANK.EQ(T39,$T$7:$T$592,0) -> 83
C40: Invesco India Large & Mid Cap Fund - Regular Plan | D40: 4 | E40: Unlock | F40: Equity: Large & MidCap | G40: 8.69 | H40: 0.98 | I40: 23.14 | J40: 13.51 | K40: 17.71 | L40: 16.59 | M40: 1.9 | N40: Very High | O40: High | P40: Direct | Q40: =I40*0.4+K40*0.5 -> 18.111 | R40: =(L40+J40)/2 -> 15.05 | S40: =(M40+K40)/2 -> 9.805 | T40: =('Investor-Inputs'!$G$19 * Q40) + ('Investor-Inputs'!$J$19 * R40) + ('Investor-Inputs'!$N$19 * S40) -> 94.238 | U40: =_xlfn.RANK.EQ(T40,$T$7:$T$592,0) -> 61
C41: Motilal Oswal Large and Midcap Fund - Regular Plan | D41: 4 | E41: Unlock | F41: Equity: Large & MidCap | G41: 15.63 | H41: 9.31 | I41: 25.52 | J41: 15.88 | K41: 20.97 | L41: 19.38 | M41: 1.91 | N41: Very High | O41: High | P41: Direct | Q41: =I41*0.4+K41*0.5 -> 20.693 | R41: =(L41+J41)/2 -> 17.63 | S41: =(M41+K41)/2 -> 11.44 | T41: =('Investor-Inputs'!$G$19 * Q41) + ('Investor-Inputs'!$J$19 * R41) + ('Investor-Inputs'!$N$19 * S41) -> 108.779 | U41: =_xlfn.RANK.EQ(T41,$T$7:$T$592,0) -> 35
C42: Nippon India Vision Large & Mid Cap Fund | D42: 4 | E42: Unlock | F42: Equity: Large & MidCap | G42: 3.77 | H42: -0.43 | I42: 19.32 | J42: 9.72 | K42: 16.65 | L42: 13.98 | M42: 1.8 | N42: Very High | O42: Above Avg. | P42: Direct | Q42: =I42*0.4+K42*0.5 -> 16.053 | R42: =(L42+J42)/2 -> 11.85 | S42: =(M42+K42)/2 -> 9.225 | T42: =('Investor-Inputs'!$G$19 * Q42) + ('Investor-Inputs'!$J$19 * R42) + ('Investor-Inputs'!$N$19 * S42) -> 81.084 | U42: =_xlfn.RANK.EQ(T42,$T$7:$T$592,0) -> 124
C43: SBI Large & Midcap Fund | D43: 4 | E43: Unlock | F43: Equity: Large & MidCap | G43: 7.36 | H43: 1 | I43: 16.09 | J43: 9.1 | K43: 16.53 | L43: 12.82 | M43: 1.72 | N43: Very High | O43: Avg. | P43: Direct | Q43: =I43*0.4+K43*0.5 -> 14.701 | R43: =(L43+J43)/2 -> 10.96 | S43: =(M43+K43)/2 -> 9.125 | T43: =('Investor-Inputs'!$G$19 * Q43) + ('Investor-Inputs'!$J$19 * R43) + ('Investor-Inputs'!$N$19 * S43) -> 75.148 | U43: =_xlfn.RANK.EQ(T43,$T$7:$T$592,0) -> 156
C44: UTI Large & Mid Cap Fund - Regular Plan | D44: 5 | E44: Unlock | F44: Equity: Large & MidCap | G44: 6.37 | H44: 2.1 | I44: 20.12 | J44: 10.84 | K44: 17.61 | L44: 15.01 | M44: 1.85 | N44: Very High | O44: Above Avg. | P44: Direct | Q44: =I44*0.4+K44*0.5 -> 16.853 | R44: =(L44+J44)/2 -> 12.925 | S44: =(M44+K44)/2 -> 9.73 | T44: =('Investor-Inputs'!$G$19 * Q44) + ('Investor-Inputs'!$J$19 * R44) + ('Investor-Inputs'!$N$19 * S44) -> 86.139 | U44: =_xlfn.RANK.EQ(T44,$T$7:$T$592,0) -> 106
C45: Aditya Birla Sun Life Flexi Cap Fund - Regular Plan | D45: 4 | E45: Unlock | F45: Equity: Flexi Cap | G45: 6.66 | H45: 2.86 | I45: 17.36 | J45: 10.21 | K45: 13.7 | L45: 12.34 | M45: 1.6 | N45: Very High | O45: Above Avg. | P45: Direct | Q45: =I45*0.4+K45*0.5 -> 13.794 | R45: =(L45+J45)/2 -> 11.275 | S45: =(M45+K45)/2 -> 7.65 | T45: =('Investor-Inputs'!$G$19 * Q45) + ('Investor-Inputs'!$J$19 * R45) + ('Investor-Inputs'!$N$19 * S45) -> 71.582 | U45: =_xlfn.RANK.EQ(T45,$T$7:$T$592,0) -> 186
...

Sheet VisualAnalysis
A1: Row Labels | B1: Average of Rank
A2: Bajaj Finserv Overnight Fund - Regular Plan | B2: 585
A3: Canara Robeco Focused Fund - Regular Plan | B3: 568
A4: Edelweiss CRISIL IBX 50:50 Gilt Plus SDL Short Duration Index Fund - Regular Plan | B4: 579
A5: Franklin India Balanced Advantage Fund - Regular Plan | B5: 577
A6: Mirae Asset Balanced Advantage Fund - Regular Plan | B6: 572
A7: Motilal Oswal 5 Year G-Sec FoF - Regular Plan | B7: 581
A8: Parag Parikh Conservative Hybrid Fund - Regular Plan | B8: 575
A9: SBI Balanced Advantage Fund - Regular Plan | B9: 570
A10: Tata Gold ETF FoF - Regular Plan | B10: 583
A11: WhiteOak Capital Large Cap Fund - Regular Plan | B11: 566
A12: Grand Total | B12: 575.6
A27: Top 10 Performance Funds Based on User Inputs
